Q1) Java try catch block:-

import java.io.IOException;

public class try_catch {
    public static void main(String[] args) {


//        try {
//            int result =5/0;
//            System.out.println(a[8]);
//
//
//
//
//        }catch (ArrayIndexOutOfBoundsException e){
//            System.out.println("tried to access the out of bound element");
//        } catch(ArithmeticException e){
//            System.out.println(e.getStackTrace());
//            System.out.println(e.getMessage());
//            System.out.println(e);
//        }

        int a[] = new int[5];
        System.out.println("hello guys");
        try {
            int result = 5 / 0;
            System.out.println(a[8]);

//        }catch (ArrayIndexOutOfBoundsException | ArithmeticException | NullPointerException e){
//            System.out.println("Handling the exception");
//        } catch(RuntimeException e){
//        }
        }catch(Exception e){
            System.out.println("all exception handled");
        }
        System.out.println("Bye guys");

    }


Q2) Arithmetic Exception.
public class Arithmetic_exception {
    public static void main(String[] args) {
        try{
            int a=10,b=0;
            int c= a/b;
            System.out.println("Result =" + c);
        }
        catch(ArithmeticException e){
            System.out.println("can't divide a number by 0");
        }
    }
}

Q3)NullPointer Exception.
public class NullPointer_exception {
    public static void main(String[] args) {
        try{
            String a= null;
            System.out.println(a.charAt(0));
        }catch(NullPointerException e) {
            System.out.println("NullPointerException");
        }
    }
}
